Workbook

Sheet Rambudget
A1: Allmän info | D1: 2026 REV | H1: 2026
D2: Intäkter | E2: Kostnader | F2: Resultat | H2: Intäkter | I2: Kostnader | J2: Resultat
A3: Totalt | D3: =SUM(D5:D108)/2 -> 2987720.9 | E3: =SUM(E5:E108)/2 -> 2979274.1 | F3: =D3-E3 -> 8446.7976 | H3: =SUM(H4:H108)/2 -> 2876915.2 | I3: =SUM(I4:I108)/2 -> 2884542.5 | J3: =H3-I3 -> -7627.3271
A4: Beteckning | B4: Kostnadsställe
A5: Aktivitetsutskottet
A6: AKTU01 | B6: {=INDIRECT(ADDRESS(ROW(B$1),COLUMN(B$1),4,TRUE,$A6))} -> Funktionärer | D6: {=INDIRECT(ADDRESS(ROW($J$6),COLUMN($J$6),4,TRUE,$A6))} -> 0 | E6: =INDIRECT(ADDRESS(ROW($J$7),COLUMN($J$7),4,TRUE,$A6)) -> 7546 | F6: =D6-E6 -> -7546 | H6: {=INDIRECT(ADDRESS(ROW($L$6),COLUMN($L$6),4,TRUE,$A6))} -> 0 | I6: =INDIRECT(ADDRESS(ROW($L$7),COLUMN($L$7),4,TRUE,$A6)) -> 15792 | J6: =H6-I6 -> -15792
A7: AKTU03 | B7: =INDIRECT(ADDRESS(ROW(B$1),COLUMN($B$1),4,TRUE,$A7)) -> UtEDischot | D7: =INDIRECT(ADDRESS(ROW($J$6),COLUMN($J$6),4,TRUE,$A7)) -> 460595 | E7: =INDIRECT(ADDRESS(ROW($J$7),COLUMN($J$7),4,TRUE,$A7)) -> 438810 | F7: =D7-E7 -> 21785 | H7: =INDIRECT(ADDRESS(ROW($L$6),COLUMN($L$6),4,TRUE,$A7)) -> 436500 | I7: =INDIRECT(ADDRESS(ROW($L$7),COLUMN($L$7),4,TRUE,$A7)) -> 415731.5 | J7: =H7-I7 -> 20768.5
A8: AKTU04 | B8: =INDIRECT(ADDRESS(ROW(B$1),COLUMN($B$1),4,TRUE,$A8)) -> Externa evenemang | D8: =INDIRECT(ADDRESS(ROW($J$6),COLUMN($J$6),4,TRUE,$A8)) -> 40000 | E8: =INDIRECT(ADDRESS(ROW($J$7),COLUMN($J$7),4,TRUE,$A8)) -> 41000 | F8: =D8-E8 -> -1000 | H8: =INDIRECT(ADDRESS(ROW($L$6),COLUMN($L$6),4,TRUE,$A8)) -> 40000 | I8: =INDIRECT(ADDRESS(ROW($L$7),COLUMN($L$7),4,TRUE,$A8)) -> 48000 | J8: =H8-I8 -> -8000
A9: AKTU07 | B9: =INDIRECT(ADDRESS(ROW(B$1),COLUMN($B$1),4,TRUE,$A9)) -> Evenemang | D9: =INDIRECT(ADDRESS(ROW($J$6),COLUMN($J$6),4,TRUE,$A9)) -> 30000 | E9: =INDIRECT(ADDRESS(ROW($J$7),COLUMN($J$7),4,TRUE,$A9)) -> 66150 | F9: =D9-E9 -> -36150 | H9: =INDIRECT(ADDRESS(ROW($L$6),COLUMN($L$6),4,TRUE,$A9)) -> 30000 | I9: =INDIRECT(ADDRESS(ROW($L$7),COLUMN($L$7),4,TRUE,$A9)) -> 66150 | J9: =H9-I9 -> -36150
A10: AKTU08 | B10: =INDIRECT(ADDRESS(ROW(B$1),COLUMN($B$1),4,TRUE,$A10)) -> Inventarie | D10: =INDIRECT(ADDRESS(ROW($J$6),COLUMN($J$6),4,TRUE,$A10)) -> 0 | E10: =INDIRECT(ADDRESS(ROW($J$7),COLUMN($J$7),4,TRUE,$A10)) -> 0 | F10: =D10-E10 -> 0 | H10: =INDIRECT(ADDRESS(ROW($L$6),COLUMN($L$6),4,TRUE,$A10)) -> 0 | I10: =INDIRECT(ADDRESS(ROW($L$7),COLUMN($L$7),4,TRUE,$A10)) -> 0 | J10: =H10-I10 -> 0
A11: Totalt aktivitetsutskottet | D11: =SUM(D6:D10) -> 530595 | E11: =SUM(E6:E10) -> 553506 | F11: =SUM(F6:F10) -> -22911 | H11: =SUM(H6:H10) -> 506500 | I11: =SUM(I6:I10) -> 545673.5 | J11: =SUM(J6:J10) -> -39173.5
A13: Cafémästeriet
A14: CAFE01 | B14: =INDIRECT(ADDRESS(ROW(B$1),COLUMN(B$1),4,TRUE,$A14)) -> Funktionärer | D14: =INDIRECT(ADDRESS(ROW($J$6),COLUMN($J$6),4,TRUE,$A14)) -> 0 | E14: =INDIRECT(ADDRESS(ROW($J$7),COLUMN($J$7),4,TRUE,$A14)) -> 28818 | F14: =D14-E14 -> -28818 | H14: =INDIRECT(ADDRESS(ROW($L$6),COLUMN($L$6),4,TRUE,$A14)) -> 0 | I14: =INDIRECT(ADDRESS(ROW($L$7),COLUMN($L$7),4,TRUE,$A14)) -> 42712 | J14: =H14-I14 -> -42712
A15: CAFE02 | B15: =INDIRECT(ADDRESS(ROW(B$1),COLUMN(B$1),4,TRUE,$A15)) -> D-café | D15: =INDIRECT(ADDRESS(ROW($J$6),COLUMN($J$6),4,TRUE,$A15)) -> 124710 | E15: =INDIRECT(ADDRESS(ROW($J$7),COLUMN($J$7),4,TRUE,$A15)) -> 98740 | F15: =D15-E15 -> 25970 | H15: =INDIRECT(ADDRESS(ROW($L$6),COLUMN($L$6),4,TRUE,$A15)) -> 141510 | I15: =INDIRECT(ADDRESS(ROW($L$7),COLUMN($L$7),4,TRUE,$A15)) -> 96220 | J15: =H15-I15 -> 45290
A16: CAFE04 | B16: =INDIRECT(ADDRESS(ROW(B$1),COLUMN(B$1),4,TRUE,$A16)) -> Övriga evenemang | D16: =INDIRECT(ADDRESS(ROW($J$6),COLUMN($J$6),4,TRUE,$A16)) -> 15000 | E16: =INDIRECT(ADDRESS(ROW($J$7),COLUMN($J$7),4,TRUE,$A16)) -> 13500 | F16: =D16-E16 -> 1500 | H16: =INDIRECT(ADDRESS(ROW($L$6),COLUMN($L$6),4,TRUE,$A16)) -> 15000 | I16: =INDIRECT(ADDRESS(ROW($L$7),COLUMN($L$7),4,TRUE,$A16)) -> 13500 | J16: =H16-I16 -> 1500
A17: Totalt cafémästeriet | D17: =sum(D14:D16) -> 139710 | E17: =sum(E14:E16) -> 141058 | F17: =sum(F14:F16) -> -1348 | H17: =sum(H14:H16) -> 156510 | I17: =sum(I14:I16) -> 152432 | J17: =sum(J14:J16) -> 4078
A19: Centralprocessutskottet
A20: CPU01 | B20: Centralprocessutskottet | D20: {=INDIRECT(ADDRESS(ROW($J$6),COLUMN($J$6),4,TRUE,$A20))} -> 0 | E20: {=INDIRECT(ADDRESS(ROW($J$7),COLUMN($J$7),4,TRUE,$A20))} -> 16755 | F20: =D20-E20 -> -16755 | H20: {=INDIRECT(ADDRESS(ROW($L$6),COLUMN($L$6),4,TRUE,$A20))} -> 0 | I20: {=INDIRECT(ADDRESS(ROW($L$7),COLUMN($L$7),4,TRUE,$A20))} -> 30658 | J20: =H20-I20 -> -30658
A21: Totalt framtidsutskottet | D21: =sum(D20) -> 0 | E21: =sum(E20) -> 16755 | F21: =sum(F20) -> -16755 | H21: =sum(H20) -> 0 | I21: =sum(I20) -> 30658 | J21: =sum(J20) -> -30658
A23: Framtidsutskottet
A24: FRA01 | B24: Allmänt | D24: {=INDIRECT(ADDRESS(ROW($J$6),COLUMN($J$6),4,TRUE,$A24))} -> 0 | E24: {=INDIRECT(ADDRESS(ROW($J$7),COLUMN($J$7),4,TRUE,$A24))} -> 6884 | F24: =D24-E24 -> -6884 | H24: {=INDIRECT(ADDRESS(ROW($L$6),COLUMN($L$6),4,TRUE,$A24))} -> 0 | I24: {=INDIRECT(ADDRESS(ROW($L$7),COLUMN($L$7),4,TRUE,$A24))} -> 14468 | J24: =H24-I24 -> -14468
A25: Totalt framtidsutskottet | D25: =sum(D24) -> 0 | E25: =sum(E24) -> 6884 | F25: =sum(F24) -> -6884 | H25: =sum(H24) -> 0 | I25: =sum(I24) -> 14468 | J25: =sum(J24) -> -14468
A27: Informationsutskottet
A28: INFU01 | B28: {=INDIRECT(ADDRESS(ROW($B$1),COLUMN($B$1),4,TRUE,$A28))} -> Allmänt | D28: =INDIRECT(ADDRESS(ROW($J$6),COLUMN($J$6),4,TRUE,$A28)) -> 0 | E28: =INDIRECT(ADDRESS(ROW($J$7),COLUMN($J$7),4,TRUE,$A28)) -> 13203 | F28: =D28-E28 -> -13203 | H28: =INDIRECT(ADDRESS(ROW($L$6),COLUMN($L$6),4,TRUE,$A28)) -> 0 | I28: =INDIRECT(ADDRESS(ROW($L$7),COLUMN($L$7),4,TRUE,$A28)) -> 19842 | J28: =H28-I28 -> -19842
A29: INFU03 | B29: {=INDIRECT(ADDRESS(ROW(B$1),COLUMN(B$1),4,TRUE,$A29))} -> D-shopen | D29: =INDIRECT(ADDRESS(ROW($J$6),COLUMN($J$6),4,TRUE,$A29)) -> 160650 | E29: =INDIRECT(ADDRESS(ROW($J$7),COLUMN($J$7),4,TRUE,$A29)) -> 127500 | F29: =D29-E29 -> 33150 | H29: =INDIRECT(ADDRESS(ROW($L$6),COLUMN($L$6),4,TRUE,$A29)) -> 160650 | I29: =INDIRECT(ADDRESS(ROW($L$7),COLUMN($L$7),4,TRUE,$A29)) -> 127500 | J29: =H29-I29 -> 33150
A30: Totalt informationsutskottet | D30: =sum(D28:D29) -> 160650 | E30: =sum(E28:E29) -> 140703 | F30: =sum(F28:F29) -> 19947 | H30: =sum(H28:H29) -> 160650 | I30: =sum(I28:I29) -> 147342 | J30: =sum(J28:J29) -> 13308
A32: Källarmästeriet
A33: KAL01 | B33: =INDIRECT(ADDRESS(ROW($B$1),COLUMN($B$1),4,TRUE,$A33)) -> Funktionärer | D33: =INDIRECT(ADDRESS(ROW($J$6),COLUMN($J$6),4,TRUE,$A33)) -> 0 | E33: =INDIRECT(ADDRESS(ROW($J$7),COLUMN($J$7),4,TRUE,$A33)) -> 15633 | F33: =D33-E33 -> -15633 | H33: =INDIRECT(ADDRESS(ROW($L$6),COLUMN($L$6),4,TRUE,$A33)) -> 0 | I33: =INDIRECT(ADDRESS(ROW($L$7),COLUMN($L$7),4,TRUE,$A33)) -> 20566 | J33: =H33-I33 -> -20566
A34: KAL04 | B34: =INDIRECT(ADDRESS(ROW($B$1),COLUMN($B$1),4,TRUE,$A34)) -> Inventarie | D34: =INDIRECT(ADDRESS(ROW($J$6),COLUMN($J$6),4,TRUE,$A34)) -> 1500 | E34: =INDIRECT(ADDRESS(ROW($J$7),COLUMN($J$7),4,TRUE,$A34)) -> 42600 | F34: =D34-E34 -> -41100 | H34: =INDIRECT(ADDRESS(ROW($L$6),COLUMN($L$6),4,TRUE,$A34)) -> 1500 | I34: =INDIRECT(ADDRESS(ROW($L$7),COLUMN($L$7),4,TRUE,$A34)) -> 42600 | J34: =H34-I34 -> -41100
A35: Totalt källarmästeriet | D35: =SUM(D33:D34) -> 1500 | E35: =SUM(E33:E34) -> 58233 | F35: =SUM(F33:F34) -> -56733 | H35: =SUM(H33:H34) -> 1500 | I35: =SUM(I33:I34) -> 63166 | J35: =SUM(J33:J34) -> -61666
A37: Medaljelelekommitén
A38: MED01 | B38: Allmänt | D38: {=INDIRECT(ADDRESS(ROW($J$6),COLUMN($J$6),4,TRUE,$A38))} -> 2500 | E38: {=INDIRECT(ADDRESS(ROW($J$7),COLUMN($J$7),4,TRUE,$A38))} -> 3035 | F38: =D38-E38 -> -535 | H38: {=INDIRECT(ADDRESS(ROW($L$6),COLUMN($L$6),4,TRUE,$A38))} -> 2500 | I38: {=INDIRECT(ADDRESS(ROW($L$7),COLUMN($L$7),4,TRUE,$A38))} -> 4420 | J38: =H38-I38 -> -1920
A39: Totalt medaljelelekommitén | D39: =sum(D38) -> 2500 | E39: =sum(E38) -> 3035 | F39: =sum(F38) -> -535 | H39: =sum(H38) -> 2500 | I39: =sum(I38) -> 4420 | J39: =sum(J38) -> -1920
A41: Näringslivsutskottet
A42: NARU01 | B42: =INDIRECT(ADDRESS(ROW(B$1),COLUMN($B$1),4,TRUE,$A42)) -> Funktionärer | D42: =INDIRECT(ADDRESS(ROW($J$6),COLUMN($J$6),4,TRUE,$A42)) -> 0 | E42: =INDIRECT(ADDRESS(ROW($J$7),COLUMN($J$7),4,TRUE,$A42)) -> 12084 | F42: =D42-E42 -> -12084 | H42: =INDIRECT(ADDRESS(ROW($L$6),COLUMN($L$6),4,TRUE,$A42)) -> 0 | I42: =INDIRECT(ADDRESS(ROW($L$7),COLUMN($L$7),4,TRUE,$A42)) -> 11840 | J42: =H42-I42 -> -11840
A43: NARU02 | B43: =INDIRECT(ADDRESS(ROW(B$1),COLUMN($B$1),4,TRUE,$A43)) -> Spons | D43: =INDIRECT(ADDRESS(ROW($J$6),COLUMN($J$6),4,TRUE,$A43)) -> 575025 | E43: =INDIRECT(ADDRESS(ROW($J$7),COLUMN($J$7),4,TRUE,$A43)) -> 319525 | F43: =D43-E43 -> 255500 | H43: =INDIRECT(ADDRESS(ROW($L$6),COLUMN($L$6),4,TRUE,$A43)) -> 600235 | I43: =INDIRECT(ADDRESS(ROW($L$7),COLUMN($L$7),4,TRUE,$A43)) -> 275535 | J43: =H43-I43 -> 324700
A44: NARU03 | B44: =INDIRECT(ADDRESS(ROW(B$1),COLUMN($B$1),4,TRUE,$A44)) -> Alumnigruppen | D44: =INDIRECT(ADDRESS(ROW($J$6),COLUMN($J$6),4,TRUE,$A44)) -> 30250 | E44: =INDIRECT(ADDRESS(ROW($J$7),COLUMN($J$7),4,TRUE,$A44)) -> 27000 | F44: =D44-E44 -> 3250 | H44: =INDIRECT(ADDRESS(ROW($L$6),COLUMN($L$6),4,TRUE,$A44)) -> 30250 | I44: =INDIRECT(ADDRESS(ROW($L$7),COLUMN($L$7),4,TRUE,$A44)) -> 27000 | J44: =H44-I44 -> 3250
A45: Totalt näringsliv | D45: =SUM(D42:D44) -> 605275 | E45: =SUM(E42:E44) -> 358609 | F45: =SUM(F42:F44) -> 246666 | H45: =SUM(H42:H44) -> 630485 | I45: =SUM(I42:I44) -> 314375 | J45: =SUM(J42:J44) -> 316110
A47: Nollningsutskottet
A48: NOLL01 | B48: =INDIRECT(ADDRESS(ROW(B$1),COLUMN($B$1),4,TRUE,$A48)) -> Funktionärer | D48: =INDIRECT(ADDRESS(ROW($J$6),COLUMN($J$6),4,TRUE,$A48)) -> 10000 | E48: =INDIRECT(ADDRESS(ROW($J$7),COLUMN($J$7),4,TRUE,$A48)) -> 45519 | F48: =D48-E48 -> -35519 | H48: =INDIRECT(ADDRESS(ROW($L$6),COLUMN($L$6),4,TRUE,$A48)) -> 10000 | I48: =INDIRECT(ADDRESS(ROW($L$7),COLUMN($L$7),4,TRUE,$A48)) -> 69868 | J48: =H48-I48 -> -59868
...

Sheet Parametrar
A1: Parametrar
A2: För att enklara justera generella kostnader / parametrar för budgeten
A4: Namn / Reglering | I4: 2026 REV | K4: 2026
A6: Schablonkostnader
A7: Prisbasbelopp | I7: 59200 | K7: 59200
A8: Tack enl. policy | I8: =ROUND(0.0035*I7,0) -> 207 | K8: =ROUND(0.007*K7,0) -> 414
A9: Tröja enl. policy | I9: 350 | K9: 350
A10: Mat | I10: 0 | K10: 0
A13: Fortnox Licenskostnad (styck pris ink. moms)
A14: Fortnox — Bokföring | I14: 271.25
A15: Fortnox — Bokföring (för bokslut) | I15: 173.75
A16: Fortnox — Offert och order | I16: 142.5
A17: Fortnox — Fakturering | I17: 213.75
A18: Fortnox — Läs (Revisorer) | I18: 142.5
A19: Fortnox — Integration | I19: 271.25
A22: Alkohol
A23: FÖREGÅENDE ÅR - Ölkostnad | I23: 109538.8 | K23: 0
A24: FÖREGÅENDE ÅR - Övrig jäst dryckförsäljning | I24: 45749.38 | K24: 0
A25: FÖREGÅENDE ÅR - Vinkostnad | I25: 85382.75 | K25: 0
A26: FÖREGÅENDE ÅR - Spritdrycksförsäljning | I26: 94466.5 | K26: 0
A28: FÖREGÅENDE ÅR - Ölförsäljning | I28: 143692.91
A29: FÖREGÅENDE ÅR - Övrig jäst dryckförsäljning | I29: 40053.29
A30: FÖREGÅENDE ÅR - Vinförsäljning | I30: 112526.38
A31: FÖREGÅENDE ÅR - Spritdrycksförsäljning | I31: 289142.2
G32: (karnevalen kommer påverka våra säljsiffror)
A33: GENOMSNITTLIGT Påslag öl | E33: 1.6 | F33: x | G33: 0.9 | H33: = | I33: =E33*G33 -> 1.44 | K33: 0
A34: GENOMSNITTLIGT Påslag övrig jäst dryck | E34: 1.5 | F34: x | G34: 0.9 | H34: = | I34: =E34*G34 -> 1.35 | K34: 0
A35: GENOMSNITTLIGT Påslag vin | E35: 1.6 | F35: x | G35: 0.9 | H35: = | I35: =E35*G35 -> 1.44 | K35: 0
A36: GENOMSNITTLIGT Påslag spritdryck | E36: 3 | F36: x | G36: 0.9 | H36: = | I36: =E36*G36 -> 2.7 | K36: 0
A39: Sittning | M39: Sanity check
A40: Andel av total ölförsäljning | E40: =50792.01+1240.91 -> 52032.92 | F40: / | G40: =I28 -> 143692.91 | H40: = | I40: =E40/G40+I70 -> 0.44214367 | K40: 0 | M40: ÖL | N40: =I40+I46+I52+I58+I64 -> 1
A41: Andel av total ciderförsäljning | E41: 12172.69 | F41: / | G41: =I29 -> 40053.29 | H41: = | I41: =E41/G41+I71 -> 0.35558352 | K41: 0 | M41: Cider | N41: =I41+I47+I53+I59+I65 -> 1
A42: Andel av total vinförsäljning | E42: 60828.38 | F42: / | G42: =I30 -> 112526.38 | H42: = | I42: =E42/G42+I72 -> 0.5648487 | K42: 0 | M42: Vin | N42: =I42+I48+I54+I60+I66 -> 1
A43: Andel av total spritförsäljning | E43: 114126.2 | F43: / | G43: =I31 -> 289142.2 | H43: = | I43: =E43/G43+I73 -> 0.45892367 | K43: 0 | M43: Sprit | N43: =I43+I49+I55+I61+I67 -> 1
A45: Pub
A46: Andel av total ölförsäljning | E46: 47040 | F46: / | G46: =I28 -> 143692.91 | H46: = | I46: =E46/G46 -> 0.32736479 | K46: 0
A47: Andel av total ciderförsäljning | E47: 13166 | F47: / | G47: =I29 -> 40053.29 | H47: = | I47: =E47/G47 -> 0.32871207 | K47: 0
A48: Andel av total vinförsäljning | E48: 4131 | F48: / | G48: =I30 -> 112526.38 | H48: = | I48: =E48/G48 -> 0.036711392 | K48: 0
A49: Andel av total spritförsäljning | E49: 29433 | F49: / | G49: =I31 -> 289142.2 | H49: = | I49: =E49/G49 -> 0.1017942 | K49: 0
A51: NolleGasque
...

Sheet AKTU01
A1: AKTU01 | B1: Funktionärer
A2: Mötesfika, tack, tröjor och jobbardricka för funktionärer i aktivitetsutskottet.
J4: 2026 REV | L4: 2026
A6: Summa intäkter | J6: =J12 -> 0 | L6: =L12 -> 0
A7: Summa utgifter | J7: =J45 -> 7546 | L7: =L45 -> 15792
A8: Resultat | J8: =J6-J7 -> -7546 | L8: =L6-L7 -> -15792
A10: Konto | B10: Namn
B12: Intäkter | J12: 0 | L12: 0
A14: 4002 | B14: Jobbarmat/Mötesfika
B15: Mötesfika | J15: 0 | L15: 0
B16: Summa | J16: =SUM(J15) -> 0 | L16: =SUM(L15) -> 0
A18: 5480 | B18: Arbetskläder och skyddsmaterial
B19: Tröja t. aktivitetsansvarig | J19: 0 | L19: 350
B20: Tröja t. vice aktivitetsansvarig | J20: 0 | L20: 350
B21: Tröjor t. UtEDischoansvariga | J21: 0 | L21: 700
B22: Tröja t. karnevalsansvarig | J22: 0 | L22: 350
B23: Tröjor t. sångarstridsförmän | J23: 0 | L23: 700
B24: Tröja t. Coach | F24: 2 | G24: × | H24: =Parametrar!$I$9 -> 350 | I24: = | J24: =F24*H24 -> 700 | L24: 700
B25: Tröja t. Idrottsförman | F25: 3 | G25: × | H25: =Parametrar!$I$9 -> 350 | I25: = | J25: =F25*H25 -> 1050 | L25: 1050
B26: Summa | J26: =SUM(J19:J25) -> 1750 | L26: =SUM(L19:L25) -> 4200
A28: 7600 | B28: Tack
B29: Tack t. aktivitetsansvarig | J29: =Parametrar!$I$8 -> 207 | L29: 414
B30: Tack t. vice aktivitetsansvarig | J30: =Parametrar!$I$8 -> 207 | L30: 414
B31: Tack t. Utedischoansvariga | F31: 2 | G31: × | H31: =Parametrar!$I$8 -> 207 | I31: = | J31: =F31*H31 -> 414 | L31: 828
B32: Tack t. karnevalsansvarig | F32: 0 | G32: × | H32: =Parametrar!$I$8 -> 207 | I32: = | J32: =F32*H32 -> 0 | L32: 0
B33: Tack t. sångarstridsförmän | F33: 2 | G33: × | H33: =Parametrar!$I$8 -> 207 | I33: = | J33: =F33*H33 -> 414 | L33: 828
B34: Tack t. D-sportare | F34: 3 | G34: × | H34: =Parametrar!$I$8 -> 207 | I34: = | J34: =F34*H34 -> 621 | L34: 1242
B35: Tack t. idrottsförmän | F35: 3 | G35: × | H35: =Parametrar!$I$8 -> 207 | I35: = | J35: =F35*H35 -> 621 | L35: 1242
B36: Tack t. LAN-partyansvariga | F36: 2 | G36: × | H36: =Parametrar!$I$8 -> 207 | I36: = | J36: =F36*H36 -> 414 | L36: 828
B37: Tack t. semesterfirare | F37: 2 | G37: × | H37: =Parametrar!$I$8 -> 207 | I37: = | J37: =F37*H37 -> 414 | L37: 828
B38: Tack t. tandemgeneral | F38: 0 | G38: × | H38: =Parametrar!$I$8 -> 207 | I38: = | J38: =F38*H38 -> 0 | L38: 0
B39: Tack t. funktionärer | F39: 8 | G39: × | H39: =Parametrar!$I$8 -> 207 | I39: = | J39: =F39*H39 -> 1656 | L39: 3312
B40: Tack t. nöjesförman | F40: 2 | G40: × | H40: =Parametrar!$I$8 -> 207 | I40: = | J40: =F40*H40 -> 414 | L40: 828
B41: Tack t. coach | F41: 2 | G41: × | H41: =Parametrar!$I$8 -> 207 | I41: = | J41: =F41*H41 -> 414 | L41: 828
B42: Summa | J42: =SUM(J29:J41) -> 5796 | L42: =SUM(L29:L41) -> 11592
B45: Kostnader | J45: =SUM(J13:J44)/2 -> 7546 | L45: =SUM(L14:L44)/2 -> 15792
B47: Resultat | J47: =J12-J45 -> -7546 | L47: =L12-L45 -> -15792

Sheet AKTU03
A1: AKTU03 | B1: UtEDischot
A2: D- och E-sektionens kolossala eftersläpp på E-husets parkering.
J4: 2026 REV | L4: 2026
A6: Summa intäkter | J6: =J21 -> 460595 | L6: =L21 -> 436500
A7: Summa utgifter | J7: =J66 -> 438810 | L7: =L66 -> 415731.5
A8: Resultat | J8: =J6-J7 -> 21785 | L8: =L6-L7 -> 20768.5
A10: Konto | B10: Namn
A12: 3000 | B12: Försäljning inom Sverige
B13: Biljetter | J13: 0 | L13: 399000
B14: Märken | F14: 1321 | G14: × | H14: 25 | J14: =F14*H14 -> 33025 | L14: 37500
B15: Summa | J15: =SUM(J13:J14) -> 33025 | L15: =SUM(L13:L14) -> 436500
A17: 3015 | B17: Biljettförsäljning
B18: Biljetter | F18: 1859 | G18: × | H18: 230 | I18: = | J18: =F18*H18 -> 427570 | L18: 0
B19: Summa | J19: =SUM(J17:J18) -> 427570 | L19: =SUM(L17:L18) -> 0
B21: Intäkter | J21: =SUM(J11:J19)/2 -> 460595 | L21: =SUM(L11:L16)/2 -> 436500
A23: 4000 | B23: Inköp av varor från Sverige
B24: Märken | F24: 2000 | G24: × | H24: =7.5*0.9*1.25 -> 8.4375 | J24: =F24*H24 -> 16875 | L24: 10500
B25: Summa | J25: =SUM(J24) -> 16875 | L25: =SUM(L24) -> 10500
A27: 4310 | B27: Arrangemangskostnader
B28: Scen och teknik | J28: 99500 | L28: 99500
B29: Emballage | J29: 100000 | L29: 100000
B30: Dekor | J30: 7000 | L30: 7000
B31: Biljettarmband | J31: 3500 | L31: 3500
B32: Engångsartiklar | J32: 3000 | L32: 3000
B33: Rider | J33: 8000 | L33: 0
B34: Summa | J34: =SUM(J28:J33) -> 221000 | L34: =SUM(L28:L33) -> 213000
A36: 6150 | B36: Trycksaker
B37: Affischer | J37: 0 | L37: 0
B38: Summa | J38: =SUM(J37) -> 0 | L38: =SUM(L37) -> 0
A40: 6590 | B40: Övriga externa tjänster
B41: Sjukvårdare | J41: 20000 | L41: 12313
B42: Artist | J42: 60000 | L42: 60000
B43: Summa | J43: =SUM(J41:J42) -> 80000 | L43: =SUM(L41:L42) -> 72313
A45: 6591 | B45: Vakter
B46: Ordningsvakter | J46: 66500 | L46: 66500
B47: Summa | J47: =SUM(J46) -> 66500 | L47: =SUM(L46) -> 66500
A49: 6950 | B49: Tillståndsavgifter
B50: Alkoholtillstånd | J50: 4870 | L50: 4870
B51: Summa | J51: =SUM(J50) -> 4870 | L51: =SUM(L50) -> 4870
A53: 7600 | B53: Tack
...

Sheet AKTU04
A1: AKTU04 | B1: Externa evenemang
A2: Evenemang som inte primärt anordnas av sektionen, men som den deltar i.
J4: 2026 REV | L4: 2026
A6: Summa intäkter | J6: =J17 -> 40000 | L6: =L17 -> 40000
A7: Summa utgifter | J7: =J30 -> 41000 | L7: =L30 -> 48000
A8: Resultat | J8: =J6-J7 -> -1000 | L8: =L6-L7 -> -8000
A10: Konto | B10: Namn
A12: 3000 | B12: Försäljning inom Sverige
B13: Biljetter t. tandemstafetten | J13: 0 | L13: 0
B14: Bussbiljetter t. DÖMD | J14: 40000 | L14: 40000
B15: Summa | J15: =SUM(J13:J14) -> 40000 | L15: =SUM(L13:L14) -> 40000
B17: Intäkter | J17: =SUM(J11:J16)/2 -> 40000 | L17: =SUM(L11:L15)/2 -> 40000
A19: 4000 | B19: Inköp av varor från Sverige
B20: Biljetter t. tandemstafetten | J20: 0 | L20: 0
B21: Biljetter t. DÖMD | J21: 0 | L21: 0
B22: Summa | J22: =SUM(J20:J21) -> 0 | L22: =SUM(L20:L21) -> 0
A24: 4310 | B24: Arrangemangskostnader
B25: Tandem | J25: 0 | L25: 0
B26: Sångarstriden | J26: 1000 | L26: 8000
B27: Buss till DÖMD | J27: 40000 | L27: 40000
B28: Summa | J28: =SUM(J25:J27) -> 41000 | L28: =SUM(L25:L27) -> 48000
B30: Kostnader | J30: =SUM(J18:J29)/2 -> 41000 | L30: =SUM(L18:L29)/2 -> 48000
B32: Resultat | J32: =J17-J30 -> -1000 | L32: =L17-L30 -> -8000

Sheet AKTU07
A1: AKTU07 | B1: Evenemang
A2: Evenemang som aktivitetsutskottet anordnar.
J4: 2026 REV | L4: 2026
A6: Summa intäkter | J6: =J16 -> 30000 | L6: =L16 -> 30000
A7: Summa utgifter | J7: =J38 -> 66150 | L7: =L38 -> 66150
A8: Resultat | J8: =J6-J7 -> -36150 | L8: =L6-L7 -> -36150
A10: Konto | B10: Namn
A12: 3000 | B12: Försäljning inom Sverige
B13: Biljettförsäljning | J13: 30000 | L13: 30000
B14: Summa | J14: =SUM(J13) -> 30000 | L14: =L13 -> 30000
B16: Intäkter | J16: =SUM(J11:J15)/2 -> 30000 | L16: =SUM(L11:L15)/2 -> 30000
A18: 4310 | B18: Arrangemangskostnader, övrigt
B19: Arrangemangskostnader | J19: 30000 | L19: 30000
B20: Summa | J20: =SUM(J19) -> 30000 | L20: =SUM(L19) -> 30000
A22: 4311 | B22: Kostnader för frilufts- och idrottsarrangemang
B23: Veckovis idrott | F23: 30 | G23: × | H23: 375 | I23: = | J23: =F23*H23 -> 11250 | L23: 24650
B24: DICK planbokning | J24: =13400-J25 -> 9600 | L24: 0
B25: Korpenavgift | F25: 2 | G25: × | H25: 1900 | I25: = | J25: =F25*H25 -> 3800 | L25: 0
B26: Startavgift t. Lundaloppet | J26: 0 | L26: 0
B27: Övrigt | J27: 1000 | L27: 1000
B28: Summa | J28: =SUM(J23:J27) -> 25650 | L28: =SUM(L23:L27) -> 25650
A30: 8610 | B30: Subventioner
B31: DÖMD | J31: 0 | L31: 0
B32: Tandem | J32: 0 | L32: 0
B33: AktU-veckan | J33: 5000 | L33: 5000
B34: Brädfika | J34: 0 | L34: 0
B35: Övrigt | J35: 5500 | L35: 5500
B36: Summa | J36: =SUM(J31:J35) -> 10500 | L36: =SUM(L31:L35) -> 10500
B38: Kostnader | J38: =SUM(J17:J37)/2 -> 66150 | L38: =SUM(L17:L37)/2 -> 66150
B40: Resultat | J40: =J16-J38 -> -36150 | L40: =L16-L38 -> -36150

Sheet AKTU08
A1: AKTU08 | B1: Inventarie
A2: Inventarie för aktivitetsutskottet. T.ex. spel och sportutrustning
J4: 2026 REV | L4: 2026
A6: Summa intäkter | J6: =J12 -> 0 | L6: =L12 -> 0
A7: Summa utgifter | J7: =J21 -> 0 | L7: =L21 -> 0
A8: Resultat | J8: =J6-J7 -> 0 | L8: =L6-L7 -> 0
A10: Konto | B10: Namn
B12: Intäkter | J12: 0 | L12: 0
A14: 5410 | B14: Förbrukningsinventarie
B15: Idrottsutrustning | J15: 0 | L15: 0
B16: Idrottströjor | J16: 0 | L16: 0
B17: Konsoller | J17: 0 | L17: 0
B18: Brädspel | J18: 0 | L18: 0
B19: Summa | J19: =SUM(J15:J18) -> 0 | L19: =SUM(L15:L18) -> 0
B21: Kostnader | J21: =SUM(J13:J20)/2 -> 0 | L21: =SUM(L15:L19)/2 -> 0
B23: Resultat | J23: =J12-J21 -> 0 | L23: =L12-L21 -> 0

Sheet CAFE01
A1: CAFE01 | B1: Funktionärer
A2: Mötesfika, tack, tröjor, jobbarmat och jobbardricka för funktionärer i cafémästeriet.
J4: 2026 REV | L4: 2026
A6: Summa intäkter | J6: =J12 -> 0 | L6: =L12 -> 0
A7: Summa utgifter | J7: =J42 -> 28818 | L7: =L42 -> 42712
A8: Resultat | J8: =J6-J7 -> -28818 | L8: =L6-L7 -> -42712
A10: Konto | B10: Namn
B12: Intäkter | J12: 0 | L12: 0
A14: 4002 | B14: Jobbarmat/Mötesfika
B15: Läsperioder | F15: 4
B16: Läsveckor | F16: 7
B17: Öppetdagar per vecka | F17: 3
B18: Luncher per dag (1 per funkispass och 3 för dagisar) | F18: 7
B20: Jobbarmat | F20: =F15*F16*F17*F18 -> 588 | G20: × | H20: 30 | I20: = | J20: =F20*H20 -> 17640 | L20: 15456
B21: Mötesfika | J21: 0 | L21: 0
B22: Summa | J22: =SUM(J15:J21) -> 17640 | L22: =SUM(L20:L21) -> 15456
A24: 5480 | B24: Arbetskläder och skyddsmaterial
B25: Tröja t. cafémästare | J25: 0 | L25: 350
B26: Tröja t. vice cafémästare | J26: 0 | L26: 350
B27: Tröja t. brunchmästare | J27: 0 | L27: 700
B28: Tröjor t. dagsansvariga | J28: 0 | L28: 2800
B29: Tröjor t. inventarieansvariga | J29: 0 | L29: 700
B30: Summa | J30: =SUM(J25:J29) -> 0 | L30: =SUM(L25:L29) -> 4900
A32: 7600 | B32: Tack
B33: Tack t. cafémästare | J33: =Parametrar!$I$8 -> 207 | L33: 414
B34: Tack t. vice cafémästare | J34: =Parametrar!$I$8 -> 207 | L34: 414
B35: Tack t. brunchmästare | F35: 2 | G35: × | H35: =Parametrar!$I$8 -> 207 | J35: =F35*H35 -> 414 | L35: 828
B36: Tack t. dagsansvariga | F36: 8 | G36: × | H36: =Parametrar!$I$8 -> 207 | I36: = | J36: =F36*H36 -> 1656 | L36: 3312
B37: Tack t. inventarieansvariga | F37: 2 | G37: × | H37: =Parametrar!$I$8 -> 207 | I37: = | J37: =F37*H37 -> 414 | L37: 828
B38: Tack t. Bakis | F38: 5 | G38: x | H38: =Parametrar!$I$8 -> 207 | I38: = | J38: =F38*H38 -> 1035 | L38: 2070
B39: Tack t. funktionärer | F39: 35 | G39: × | H39: =Parametrar!$I$8 -> 207 | I39: = | J39: =F39*H39 -> 7245 | L39: 14490
B40: Summa | J40: =SUM(J33:J39) -> 11178 | L40: =SUM(L33:L39) -> 22356
B42: Kostnader | J42: =SUM(J13:J41)/2 -> 28818 | L42: =SUM(L13:L41)/2 -> 42712
B44: Resultat | J44: =J12-J42 -> -28818 | L44: =L12-L42 -> -42712

Sheet CAFE02
A1: CAFE02 | B1: D-café
A2: Kostnader och intäkter för daglig kaféverksamhet.
J4: 2026 REV | L4: 2026
A6: Summa intäkter | J6: =J25 -> 124710 | L6: =L25 -> 141510
A7: Summa utgifter | J7: =J35 -> 98740 | L7: =L35 -> 96220
A8: Resultat | J8: =J6-J7 -> 25970 | L8: =L6-L7 -> 45290
A10: Konto | B10: Namn
B12: Öppetdagar | D12: =PRODUCT(CAFE01!F15:F17) -> 84
B13: Dryck om dagen | D13: 40
B14: Mackor om dagen | D14: 25
B15: Snacks om dagen | D15: 0
A17: 3000 | B17: Försäljning av varor i Sverige
B18: Dryck | D18: =D12 -> 84 | E18: × | F18: =D13 -> 40 | G18: × | H18: 11 | I18: = | J18: =D12*D13*H18 -> 36960 | L18: 36960
B19: Mat | D19: =D12 -> 84 | E19: × | F19: =D14 -> 25 | G19: × | H19: 40 | I19: = | J19: =D19*D14*H19 -> 84000 | L19: 100800
B20: Snacks och godis | D20: =D12 -> 84 | E20: × | F20: =D15 -> 0 | G20: × | H20: 6 | I20: = | J20: =D20*F20*H20 -> 0 | L20: 0
B21: Hembakat | F21: 250 | G21: × | H21: 15 | I21: = | J21: =F21*H21 -> 3750 | L21: 3750
B22: Glass | F22: 0 | G22: × | H22: 15 | I22: = | J22: =F22*H22 -> 0 | L22: 0
B23: Summa | J23: =SUM(J18:J22) -> 124710 | L23: =SUM(L18:L22) -> 141510
B25: Intäkter | J25: =SUM(J11:J24)/2 -> 124710 | L25: =SUM(L11:L24)/2 -> 141510
A27: 4101 | B27: Livsmedel till försäljning
B28: Dryck | D28: =D12 -> 84 | E28: × | F28: =D13 -> 40 | G28: × | H28: 9 | I28: = | J28: =D28*F28*H28 -> 30240 | L28: 30240
B29: Mat | D29: =D12 -> 84 | E29: × | F29: =D14 -> 25 | G29: × | H29: =30 -> 30 | I29: = | J29: =D29*F29*H29 -> 63000 | L29: 60480
B30: Hembakat | F30: =F21 -> 250 | G30: × | H30: =H21*0.4 -> 6 | I30: = | J30: =F30*H30 -> 1500 | L30: 1500
B31: Snacks och godis | D31: =D12 -> 84 | E31: × | F31: =D15 -> 0 | G31: × | H31: 4.8 | I31: = | J31: =D31*F31*H31 -> 0 | L31: 0
B32: Engångsartiklar | J32: 4000 | L32: 4000
B33: Summa | J33: =SUM(J28:J32) -> 98740 | L33: =SUM(L28:L32) -> 96220
B35: Kostnader | J35: =SUM(J26:J34)/2 -> 98740 | L35: =SUM(L26:L34)/2 -> 96220
B37: Resultat | J37: =J25-J35 -> 25970 | L37: =L25-L35 -> 45290

Sheet CAFE04
A1: CAFE04 | B1: Övriga evenemang
A2: Övriga evenemang som cafémästeriet håller i. T.ex. bruncher.
J4: 2026 REV | L4: 2026
A6: Summa intäkter | J6: =J16 -> 15000 | L6: =L16 -> 15000
A7: Summa utgifter | J7: =J22 -> 13500 | L7: =L22 -> 13500
A8: Resultat | J8: =J6-J7 -> 1500 | L8: =L6-L7 -> 1500
A10: Konto | B10: Namn
A12: 3015 | B12: Biljettförsäljning
B13: Biljettförsäljning | F13: 300 | G13: × | H13: 50 | I13: = | J13: =F13*H13 -> 15000 | L13: 15000
B14: Summa | J14: =SUM(J13) -> 15000 | L14: =SUM(L13) -> 15000
B16: Intäkter | J16: =SUM(J11:J15)/2 -> 15000 | L16: =SUM(L11:L15)/2 -> 15000
A18: 4310 | B18: Arrangemangskostnader
B19: Mat + evenemangspecifikt | F19: 300 | G19: × | H19: 45 | I19: = | J19: =F19*H19 -> 13500 | L19: 13500
B20: Summa | J20: =SUM(J19) -> 13500 | L20: =SUM(L19) -> 13500
B22: Kostnader | J22: =SUM(J17:J21)/2 -> 13500 | L22: =SUM(L17:L21)/2 -> 13500
B24: Resultat | J24: =J16-J22 -> 1500 | L24: =L16-L22 -> 1500

Sheet CPU01
A1: CPU01 | B1: Centralprocessutskottet
A2: Övriga evenemang som cafémästeriet håller i. T.ex. bruncher.
J4: 2026 REV | L4: 2026
A6: Summa intäkter | J6: =J12 -> 0 | L6: =L12 -> 0
A7: Summa utgifter | J7: =J44 -> 16755 | L7: =L44 -> 30658
A8: Resultat | J8: =J6-J7 -> -16755 | L8: =L6-L7 -> -30658
A10: Konto | B10: Namn
B12: Intäkter | J12: =SUM(J11)/2 -> 0 | L12: 0
A14: 4000 | B14: Inköp av varor från Sverige
B15: Hårdvara | J15: 1000 | L15: 7500
B16: Summa | J16: =SUM(J15) -> 1000 | L16: =SUM(L15) -> 7500
A18: 4002 | B18: Jobbarmat/Mötesfika
B19: CPU-kvällar | J19: 7250 | L19: 7250
B20: Summa | J20: =SUM(J19) -> 7250 | L20: =SUM(L19) -> 7250
A22: 5420 | B22: Programvaror
B23: Domäner | J23: 1502 | L23: 1502
B24: Apple Developer | J24: 1000 | L24: 1000
B25: Expo (appbyggen) | J25: 0 | L25: 0
B26: Summa | J26: =SUM(J23:J25) -> 2502 | L26: =SUM(L23:L25) -> 2502
A28: 5480 | B28: Arbetskläder och skyddsmaterial
B29: Tröja t. Mästare | J29: 0 | L29: 350
B30: Tröja t. Vice | J30: 0 | L30: 350
B31: Tröja t. root | J31: 0 | L31: 350
B32: Tröja t. DWWW-ansvarig | J32: 0 | L32: 350
B33: Summa | J33: =SUM(J29:J32) -> 0 | L33: =SUM(L29:L32) -> 1400
A35: 7600 | B35: Tack
B36: Tack t. Mästare | J36: =Parametrar!$I$8 -> 207 | L36: 414
B37: Tack t. Vice | J37: =Parametrar!$I$8 -> 207 | L37: 414
B38: Tack t. root | J38: =Parametrar!$I$8 -> 207 | L38: 414
B39: Tack t. DWWW-ansvarig | J39: =Parametrar!$I$8 -> 207 | L39: 414
B40: Tack t. Utvecklare | F40: 10 | G40: x | H40: =Parametrar!$I$8 -> 207 | I40: = | J40: =F40*H40 -> 2070 | L40: 4140
B41: Tack t. funktionärer | F41: 15 | G41: x | H41: =Parametrar!$I$8 -> 207 | I41: = | J41: =F41*H41 -> 3105 | L41: 6210
B42: Summa | J42: =SUM(J36:J41) -> 6003 | L42: =SUM(L36:L41) -> 12006
B44: Kostnader | J44: =SUM(J13:J43)/2 -> 16755 | L44: =SUM(L13:L43)/2 -> 30658
B46: Resultat | J46: =J12-J44 -> -16755 | L46: =L12-L44 -> -30658

Sheet FRA01
A1: FRA01 | B1: Allmänt
A2: Framtidsutskottets hela budget.
J4: 2026 REV | L4: 2026
A6: Summa intäkter | J6: =J12 -> 0 | L6: =L12 -> 0
A7: Summa utgifter | J7: =J34 -> 6884 | L7: =L34 -> 14468
A8: Resultat | J8: =J6-J7 -> -6884 | L8: =L6-L7 -> -14468
A10: Konto | B10: Namn
B12: Intäkter | J12: 0 | L12: 0
A14: 4002 | B14: Mötesfika/Jobbarmat
B15: Mötesfika | J15: 0 | L15: 0
B16: Mat t. långa möten | D16: 2 | E16: × | F16: 12 | G16: × | H16: =Parametrar!I10 -> 0 | I16: = | J16: =D16*F16*H16 -> 0 | L16: 0
B17: Summa | J17: =SUM(J15:J16) -> 0 | L17: =SUM(L15:L16) -> 0
A19: 4310 | B19: Arrangemangskostnader
B20: Evenemang med mat | J20: 4400 | L20: 4400
B21: Evenemang med fika | J21: 0 | L21: 900
B22: Summa | J22: =SUM(J20:J21) -> 4400 | L22: =SUM(L20:L21) -> 5300
A24: 5480 | B24: Arbetskläder och skyddsmaterial
B25: Tröja t. framtidsordförande | J25: 0 | L25: 350
B26: Tröjor t. framtidsledamöter | J26: 0 | L26: 3850
B27: Summa | J27: =SUM(J25:J26) -> 0 | L27: =SUM(L25:L26) -> 4200
A29: 7600 | B29: Tack
B30: Tack t. framtidsordföranden | J30: =Parametrar!$I$8 -> 207 | L30: 414
B31: Tack t. framtidsledamöter | F31: 11 | G31: × | H31: =Parametrar!$I$8 -> 207 | I31: = | J31: =F31*H31 -> 2277 | L31: 4554
B32: Summa | J32: =SUM(J30:J31) -> 2484 | L32: =SUM(L30:L31) -> 4968
B34: Kostnader | J34: =SUM(J13:J33)/2 -> 6884 | L34: =SUM(L13:L33)/2 -> 14468
B36: Resultat | J36: =J12-J34 -> -6884 | L36: =L12-L34 -> -14468

Sheet INFU01
A1: INFU01 | B1: Allmänt
A2: Mötesfika, tack och övriga utgifter för informationsutskottet.
J4: 2026 REV | L4: 2026
A6: Summa intäkter | J6: =J12 -> 0 | L6: =L12 -> 0
A7: Summa utgifter | J7: =J48 -> 13203 | L7: =L48 -> 19842
A8: Resultat | J8: =J6-J7 -> -13203 | L8: =L6-L7 -> -19842
A10: Konto | B10: Namn
B12: Intäkter | J12: 0 | L12: 0
A14: 4002 | B14: Jobbarmat/Mötesfika
B15: Mötesfika | J15: 0 | L15: 0
B16: InfU-kvällsmat och mötesfika | J16: 6000 | L16: 6000
B17: Summa | J17: =SUM(J15:J16) -> 6000 | L17: =SUM(L15:L16) -> 6000
A19: 5420 | B19: Programvaror
B20: Adobe Creative Cloud | J20: 0 | L20: 0
B21: Canva pro | J21: 1200 | L21: 1200
B22: Apple Developer | J22: 0 | L22: 0
B23: Kameramjukvara | J23: 0 | L23: 0
B24: Spotify | F24: 0 | G24: x | H24: 119 | J24: =F24*H24 -> 0 | L24: 0
B25: Summa | J25: =SUM(J20:J24) -> 1200 | L25: =SUM(L20:L24) -> 1200
A27: 5480 | B27: Arbetskläder och skyddsmaterial
B28: Tröja t. informationsansvarig | J28: 0 | L28: 350
B29: Tröja t. vice informationsansvarig | J29: 0 | L29: 350
B30: Tröja t. ShopaholiC | J30: 0 | L30: 350
B31: Summa | J31: =SUM(J28:J30) -> 0 | L31: =SUM(L28:L30) -> 1050
A33: 7600 | B33: Tack
B34: Tack t. informationsansvarig | J34: =Parametrar!$I$8 -> 207 | L34: 414
B35: Tack t. vice informationsansvarig | J35: =Parametrar!$I$8 -> 207 | L35: 414
B36: Tack t. arkivarier | F36: 3 | G36: × | H36: =Parametrar!$I$8 -> 207 | I36: = | J36: =F36*H36 -> 621 | L36: 1242
B37: Tack t. artister | F37: 3 | G37: × | H37: =Parametrar!$I$8 -> 207 | I37: = | J37: =F37*H37 -> 621 | L37: 1242
B38: Tack t. filmare | F38: 3 | G38: × | H38: =Parametrar!$I$8 -> 207 | I38: = | J38: =F38*H38 -> 621 | L38: 1242
B39: Tack t. fotografer | F39: 3 | G39: × | H39: =Parametrar!$I$8 -> 207 | I39: = | J39: =F39*H39 -> 621 | L39: 1242
B40: Tack t. redaktör | F40: 1 | G40: x | H40: =Parametrar!$I$8 -> 207 | I40: = | J40: =F40*H40 -> 207 | L40: 414
B41: Tack t. shopaholic | F41: 1 | G41: × | H41: =Parametrar!$I$8 -> 207 | I41: = | J41: =F41*H41 -> 207 | L41: 414
B42: Tack t. märkvärdiga | F42: 2 | G42: × | H42: =Parametrar!$I$8 -> 207 | I42: = | J42: =H42*F42 -> 414 | L42: 828
B43: Tack t. skald | F43: 1 | G43: × | H43: =Parametrar!$I$8 -> 207 | I43: = | J43: =F43*H43 -> 207 | L43: 0
B44: Tack t. journalist | F44: 3 | G44: x | H44: =Parametrar!$I$8 -> 207 | J44: =F44*H44 -> 621 | L44: 1242
B45: Tack t. funktionärer | F45: 7 | G45: × | H45: =Parametrar!$I$8 -> 207 | I45: = | J45: =F45*H45 -> 1449 | L45: 2898
B46: Summa | J46: =SUM(J34:J45) -> 6003 | L46: =SUM(L34:L45) -> 11592
B48: Kostnader | J48: =SUM(J13:J47)/2 -> 13203 | L48: =SUM(L13:L47)/2 -> 19842
B50: Resultat | J50: =J12-J48 -> -13203 | L50: =L12-L48 -> -19842

Sheet INFU03
A1: INFU03 | B1: D-shopen
A2: Sektionens affär för märken, merch och liknande.
J4: 2026 REV | L4: 2026
A6: Summa intäkter | J6: =J19 -> 160650 | L6: =L19 -> 160650
A7: Summa utgifter | J7: =J32 -> 127500 | L7: =L32 -> 127500
A8: Resultat | J8: =J6-J7 -> 33150 | L8: =L6-L7 -> 33150
A10: Konto | B10: Namn
A12: 3000 | B12: Försäljning inom Sverige
B13: Tygmärken | J13: 37000 | L13: 37000
B14: Ouveraller | F14: 190 | G14: × | H14: 435 | I14: = | J14: =F14*H14 -> 82650 | L14: 82650
B15: Sektionsmerch | J15: 15000 | L15: 15000
B16: Sångböcker | J16: 26000 | L16: 26000
B17: Summa | J17: =SUM(J13:J16) -> 160650 | L17: =SUM(L13:L16) -> 160650
B19: Intäkter | J19: =SUM(J17) -> 160650 | L19: =SUM(L11:L18)/2 -> 160650
A21: 4000 | B21: Inköp av varor från Sverige
B22: Tygmärken | J22: 35000 | L22: 35000
B23: Ouveraller | F23: 200 | G23: × | H23: 412.5 | I23: = | J23: =H23*F23 -> 82500 | L23: 82500
B24: Sektionsmerch | J24: 10000 | L24: 10000
B25: Sångböcker | J25: 0 | L25: 0
B26: Summa | J26: =SUM(J22:J25) -> 127500 | L26: =SUM(L22:L25) -> 127500
A28: 5420 | B28: Programvaror
B29: Adobe creative cloud | J29: 0 | L29: 0
B30: Summa | J30: =SUM(J29) -> 0 | L30: 0
B32: Kostnader | J32: =SUM(J20:J31)/2 -> 127500 | L32: =SUM(L20:L31)/2 -> 127500
B34: Resultat | J34: =J19-J32 -> 33150 | L34: =L19-L32 -> 33150

Sheet KAL01
A1: KAL01 | B1: Funktionärer
A2: Mötesfika, tröjor och tack för källarmästeriet.
J4: 2026 REV | L4: 2026
A6: Summa intäkter | J6: =J12 -> 0 | L6: 0
A7: Summa utgifter | J7: =J39 -> 15633 | L7: =L39 -> 20566
A8: Resultat | J8: =J6-J7 -> -15633 | L8: =L6-L7 -> -20566
A10: Konto | B10: Namn
B12: Intäkter | J12: 0 | L12: 0
A14: 4002 | B14: Jobbarmat/Mötesfika
B15: Fixarkvällsmat | J15: 4000 | L15: 4000
B16: Snickerboamat | J16: 7000 | L16: 7000
B17: Summa | J17: =SUM(J15:J16) -> 11000 | L17: =SUM(L15:L16) -> 11000
A19: 4310 | B19: Arrangemangskostnader
B20: Pepparkakshusbyggartävling | J20: 0 | L20: 1000
B21: Summa | J21: =SUM(J20) -> 0 | L21: =SUM(L20) -> 1000
A23: 5480 | B23: Arbetskläder och skyddsmaterial
B24: Tröja t. källarmästare | J24: =Parametrar!$I$9 -> 350 | L24: 350
B25: Tröja t. vice källarmästare | J25: =Parametrar!$I$9 -> 350 | L25: 350
B26: Tröja t. root | J26: 0 | L26: 0
B27: Tröja t. vice root | J27: 0 | L27: 0
B28: Summa | J28: =SUM(J24:J27) -> 700 | L28: =SUM(L24:L27) -> 700
A30: 7600 | B30: Tack
B31: Tack t. källarmästare | J31: =Parametrar!$I$8 -> 207 | L31: 414
B32: Tack t. vice källarmästare | J32: =Parametrar!$I$8 -> 207 | L32: 414
B33: Tack t. trädgårdsmästare | F33: 2 | G33: × | H33: =Parametrar!$I$8 -> 207 | I33: = | J33: =F33*H33 -> 414 | L33: 828
B34: Tack t. ljud och ljus-ansvariga | F34: 5 | G34: × | H34: =Parametrar!$I$8 -> 207 | I34: = | J34: =F34*H34 -> 1035 | L34: 2070
B35: Tack t. bilansvariga | F35: 2 | G35: × | H35: =Parametrar!$I$8 -> 207 | I35: = | J35: =F35*H35 -> 414 | L35: 828
B36: Tack t. funktionärer | F36: 8 | G36: × | H36: =Parametrar!$I$8 -> 207 | I36: = | J36: =F36*H36 -> 1656 | L36: 3312
B37: Summa | J37: =SUM(J31:J36) -> 3933 | L37: =SUM(L31:L36) -> 7866
B39: Kostnader | J39: =SUM(J13:J38)/2 -> 15633 | L39: =SUM(L14:L38)/2 -> 20566
B41: Resultat | J41: =J12-J39 -> -15633 | L41: =L12-L39 -> -20566

Sheet KAL04
A1: KAL04 | B1: Inventarie
A2: Underhåll av iDét samt inköp av nya inventarier och verktyg.
J4: 2026 REV | L4: 2026
A6: Summa intäkter | J6: =J20 -> 1500 | L6: =L20 -> 1500
A7: Summa utgifter | J7: =J30 -> 42600 | L7: =L30 -> 42600
A8: Resultat | J8: =J6-J7 -> -41100 | L8: =L6-L7 -> -41100
A10: Konto | B10: Namn
A12: 3000 | B12: Försäljning inom Sverige
B13: Materialförsäljning | J13: =J26 -> 500 | L13: 500
B14: Summa | J14: =SUM(J12:J13) -> 500 | L14: =SUM(L13) -> 500
A16: 3911 | B16: Hyresintäkter
B17: Uthyrning av inventarier | J17: 1000 | L17: 1000
B18: Summa | J18: =SUM(J17) -> 1000 | L18: =SUM(L17) -> 1000
B20: Intäkter | J20: =SUM(J11:J19)/2 -> 1500 | L20: =SUM(L11:L19)/2 -> 1500
A22: 4000 | B22: Inköp av varor från Sverige
B23: Växter | J23: 1100 | L23: 1100
B24: Lokalinventarier | J24: 35000 | L24: 35000
B25: Ljud och ljus | J25: 1000 | L25: 1000
B26: För materialförsäljning | J26: 500 | L26: 500
B27: Kioskfärg | J27: 5000 | L27: 5000
B28: Summa | J28: =SUM(J23:J27) -> 42600 | L28: =SUM(L23:L27) -> 42600
B30: Kostnader | J30: =SUM(J21:J29)/2 -> 42600 | L30: =SUM(L21:L29)/2 -> 42600
B32: Resultat | J32: =J20-J30 -> -41100 | L32: =L20-L30 -> -41100

Sheet MED01
A1: MED01 | B1: Allmänt
A2: Medaljelelekommiténs hela budget.
J4: 2026 REV | L4: 2026
A6: Summa intäkter | J6: =J16 -> 2500 | L6: 2500
A7: Summa utgifter | J7: =J36 -> 3035 | L7: 4420
A8: Resultat | J8: =J6-J7 -> -535 | L8: -1920
A10: Konto | B10: Namn
A12: 3000 | B12: Försäljning av varor i Sverige
B13: Frackband m.m. | J13: 2500 | L13: 2500
B14: Summa | J14: =SUM(J13) -> 2500 | L14: 2500
B16: Intäkter | J16: =SUM(J14) -> 2500 | L16: 2500
A18: 4000 | B18: Inköp av varor från Sverige
B19: Medaljer | J19: 1000 | L19: 1000
B20: Frackband | J20: 1000 | L20: 1000
B21: Summa | J21: =SUM(J19:J20) -> 2000 | L21: 2000
A23: 4002 | B23: Jobbarmat/Mötesfika
B24: Mötesfika | J24: 0 | L24: 0
B25: Summa | J25: =SUM(J24) -> 0 | L25: 0
A27: 5480 | B27: Arbetskläder och skyddsmaterial
B28: Tröja t. övermarskalk | J28: 0 | L28: 350
B29: Summa | J29: =SUM(J28) -> 0 | L29: 350
A31: 7600 | B31: Tack
B32: Tack t. övermarskalk | J32: =Parametrar!$I$8 -> 207 | L32: 414
B33: Tack t. medlemmar | F33: 4 | G33: × | H33: =Parametrar!$I$8 -> 207 | I33: = | J33: =F33*H33 -> 828 | L33: 1656
B34: Summa | J34: =SUM(J32:J33) -> 1035 | L34: 2070
B36: Kostnader | J36: =SUM(J17:J35)/2 -> 3035 | L36: 4420
B38: Resultat | J38: =J16-J36 -> -535 | L38: -1920

Sheet NARU01
A1: NARU01 | B1: Funktionärer
A2: Mötesfika, tröjor och tack för näringslivsutskottet.
J4: 2026 REV | L4: 2026
A6: Summa intäkter | J6: =J12 -> 0 | L6: 0
A7: Summa utgifter | J7: =J39 -> 12084 | L7: 11840
A8: Resultat | J8: =J6-J7 -> -12084 | L8: -11840
A10: Konto | B10: Namn
B12: Intäkter | J12: 0 | L12: 0
A14: 4002 | B14: Jobbarmat/Mötesfika
B15: Mötesfika | J15: 0 | L15: 0
B16: Summa | J16: =SUM(J15) -> 0 | L16: 0
A18: 5480 | B18: Arbetskläder och skyddsmaterial
B19: Tröja t. näringslivsansvarig | J19: =Parametrar!$I$9 -> 350 | L19: 350
B20: Tröja t. vice näringslivsansvarig | J20: =Parametrar!$I$9 -> 350 | L20: 350
B21: Tröja t. alumniansvarig | J21: =Parametrar!$I$9 -> 350 | L21: 350
B22: Tröja t. mentorsansvarig | J22: 0 | L22: 350
B23: Summa | J23: =SUM(J19:J22) -> 1050 | L23: 1400
A25: 6530 | B25: Redovisningstjänster
B26: Fortnox — Offert & Order | D26: 2 | E26: × | F26: 12 | G26: × | H26: =Parametrar!$I$16 -> 142.5 | I26: = | J26: =D26*F26*H26 -> 3420 | L26: 2376
B27: Fortnox — Fakturering | D27: 2 | E27: × | F27: 12 | G27: × | H27: =Parametrar!$I$17 -> 213.75 | I27: = | J27: =D27*F27*H27 -> 5130 | L27: 3096
B28: Summa | J28: =SUM(J26:J27) -> 8550 | L28: 5472
A30: 7600 | B30: Tack
B31: Tack t. näringslivsansvarig | J31: =Parametrar!$I$8 -> 207 | L31: 414
B32: Tack t. vice näringslivsansvarig | J32: =Parametrar!$I$8 -> 207 | L32: 414
B33: Tack t. mentorsansvarig | F33: 0 | G33: x | H33: =Parametrar!$I$8 -> 207 | J33: =F33*H33 -> 0 | L33: 0
B34: Tack t. alumniansvarig | J34: =Parametrar!$I$8 -> 207 | L34: 414
B35: Tack t. funktionärer i alumnigruppen | F35: 4 | G35: × | H35: =Parametrar!$I$8 -> 207 | I35: = | J35: =F35*H35 -> 828 | L35: 1656
B36: Tack t. funktionärer i NärU | F36: 5 | G36: × | H36: =Parametrar!$I$8 -> 207 | I36: = | J36: =F36*H36 -> 1035 | L36: 2070
B37: Summa | J37: =SUM(J31:J36) -> 2484 | L37: 4968
B39: Kostnader | J39: =SUM(J13:J38)/2 -> 12084 | L39: 11840
B41: Resultat | J41: =J12-J39 -> -12084 | L41: -11840

Sheet NARU02
A1: NARU02 | B1: Spons
A2: All sponseringsverksamhet som näringslivsutskottet gör. Värt att nämna är att stabens sponseringsarbete och intäkter för företagspubar också hamnar här.
J4: 2026 REV | L4: 2026
A6: Summa intäkter | J6: =J44 -> 575025 | L6: 600235
A7: Summa utgifter | J7: =J68 -> 319525 | L7: 275535
A8: Resultat | J8: =J6-J7 -> 255500 | L8: 324700
A10: Konto | B10: Namn
B12: Antal lunchföreläsningar | D12: 5
B13: Antal företagspubar | D13: 3
B14: Matkostnad per företagspub | D14: 7500
B15: Matkostnad per lunchföreläsning | D15: 8000
B16: Dryckkostnad per lunchföreläsning | D16: 1000
A18: 3000 | B18: Försäljning inom Sverige
B19: Lunchföreläsningar
B20: Mat | F20: =D$12 -> 5 | G20: × | H20: =D15 -> 8000 | I20: = | J20: =F20*H20 -> 40000 | L20: 56000
B21: Dryck | F21: =D$12 -> 5 | G21: × | H21: =D16 -> 1000 | I21: = | J21: =F21*H21 -> 5000 | L21: 7000
B22: Lokalbokning | F22: =D$12 -> 5 | G22: × | H22: 1505 | I22: = | J22: =F22*H22 -> 7525 | L22: 10535
B23: Premie | F23: =D$12 -> 5 | G23: × | H23: 15100 | I23: = | J23: =F23*H23 -> 75500 | L23: 105700
B25: Pubar
B26: Mat | F26: =D$13 -> 3 | G26: × | H26: 7500 | I26: = | J26: =F26*H26 -> 22500 | L26: 15000
B27: Premie | F27: =D$13 -> 3 | G27: × | H27: 19000 | I27: = | J27: =F27*H27 -> 57000 | L27: 38000
B29: Nollning
B30: Tröjspons | J30: 35000 | L30: 35000
B31: Chepsspons | J31: 25000 | L31: 25000
B32: Ryggsäck sidoplatser | F32: 5 | G32: × | H32: 27500 | I32: = | J32: =F32*H32 -> 137500 | L32: 125000
B33: Ryggsäck mittplatser | F33: 2 | G33: × | H33: 32500 | I33: = | J33: =F33*H33 -> 65000 | L33: 60000
B34: Hoodies | J34: 70000 | L34: 70000
B35: Merch | J35: 0 | L35: 0
B37: Övrigt
B38: Monter | J38: 5000 | L38: 5000
B39: Marknadsföring | J39: 10000 | L39: 43000
B40: Evenemang | J40: 20000 | L40: 20000
B41: Koppar | J41: 0 | L41: 0
B42: Summa | J42: =SUM(J20:J41) -> 575025 | L42: =SUM(L20:L41) -> 615235
B44: Intäkter | J44: =SUM(J20:J43)/2 -> 575025 | L44: =SUM(L20:L43)/2 -> 615235
A46: 4310 | B46: Arrangemangskostnader
B47: Mat t. lunchföreläsningar | F47: =D$12 -> 5 | G47: × | H47: =D15 -> 8000 | I47: = | J47: =F47*H47 -> 40000 | L47: 56000
B48: Dryck t. lunchföreläsningar | F48: =D$12 -> 5 | G48: × | H48: =D16 -> 1000 | I48: = | J48: =F48*H48 -> 5000 | L48: 7000
B49: Evenemang | J49: 2000 | L49: 2000
B50: Summa | J50: =SUM(J47:J49) -> 47000 | L50: 65000
...

Sheet NARU03
A1: NARU03 | B1: Alumnigruppen
A2: Alumnigruppens mötesfika och verksamhet.
J4: 2026 REV | L4: 2026
A6: Summa intäkter | J6: =J16 -> 30250 | L6: 30250
A7: Summa utgifter | J7: =J26 -> 27000 | L7: 27000
A8: Resultat | J8: =J6-J7 -> 3250 | L8: 3250
A10: Konto | B10: Namn
A12: 3015 | B12: Biljettförsäljning
B13: Biljettförsäljning | J13: 30250 | L13: 30250
B14: Summa | J14: =SUM(J13) -> 30250 | L14: 30250
B16: Intäkter | J16: =SUM(J11:J15)/2 -> 30250 | L16: 30250
A18: 4002 | B18: Jobbarmat/Mötesfika
B19: Mötesfika | J19: 0 | L19: 0
B20: Summa | J20: =SUM(J19) -> 0 | L20: 0
A22: 4310 | B22: Arrangemangskostnader
B23: Alumnimiddag el. motsvarande | J23: 27000 | L23: 27000
B24: Summa | J24: =SUM(J23) -> 27000 | L24: 27000
B26: Kostnader | J26: =SUM(J17:J25)/2 -> 27000 | L26: 27000
B28: Resultat | J28: =J16-J26 -> 3250 | L28: 3250

Sheet NOLL01
A1: NOLL01 | B1: Funktionärer
A2: Mötesfika, tröjor och tack för nollningsutskottet.
J4: 2026 REV | L4: 2026
A6: Summa intäkter | J6: =J16 -> 10000 | L6: 10000
A7: Summa utgifter | J7: =J47 -> 45519 | L7: 69868
A8: Resultat | J8: =J6-J7 -> -35519 | L8: -59868
A10: Konto | B10: Namn
A12: 3015 | B12: Biljettfösäljning
B13: Phadderkickoff | J13: 10000 | L13: 10000
B14: Summa | J14: =SUM(J13) -> 10000 | L14: 10000
B16: Intäkter | J16: =SUM(J11:J15)/2 -> 10000 | L16: 10000
A18: 4002 | B18: Jobbarmat/Mötesfika
B19: Mötesfika | J19: 0 | L19: 0
B20: Summa | J20: =SUM(J19) -> 0 | L20: 0
A22: 4310 | B22: Arrangemangskostnader
B23: Phaddermys | F23: 11 | G23: × | H23: 2000 | I23: = | J23: =F23*H23 -> 22000 | L23: 22000
B24: Phadderkickoff | J24: 10000 | L24: 10000
B25: Summa | J25: =SUM(J23:J24) -> 32000 | L25: 32000
A27: 5480 | B27: Arbetskläder och skyddsmaterial
B28: Tröja t. Øverphøs | J28: 0 | L28: 350
B29: Tröjor t. stabsmedlemmar | J29: 0 | L29: 1750
B30: Tröjor t. Øverpeppare | J30: 0 | L30: 700
B31: Tröjor t. peppare | J31: 0 | L31: 3150
B32: Utstyrsel t. phaddrar | F32: 124 | G32: × | H32: 0 | I32: = | J32: =F32*H32 -> 0 | L32: 14880
B33: Summa | J33: =SUM(J28:J32) -> 0 | L33: 20830
A35: 7600 | B35: Tack
B36: Tack t. Øverphøs | J36: =Parametrar!$I$8 -> 207 | L36: 414
B37: Tack t. stabsmedlemmar | F37: 5 | G37: × | H37: =Parametrar!$I$8 -> 207 | I37: = | J37: =F37*H37 -> 1035 | L37: 2070
B38: Tack t. Øverpeppare | F38: 2 | G38: × | H38: =Parametrar!$I$8 -> 207 | I38: = | J38: =F38*H38 -> 414 | L38: 828
B39: Tack t. peppare | F39: 9 | G39: × | H39: =Parametrar!$I$8 -> 207 | I39: = | J39: =F39*H39 -> 1863 | L39: 3726
B40: Tack t. funktionärer | F40: 0 | G40: × | H40: =Parametrar!$I$8 -> 207 | I40: = | J40: =F40*H40 -> 0 | L40: 0
B41: Summa | J41: =SUM(J36:J40) -> 3519 | L41: 7038
A43: 7604 | B43: Förenat tack
B44: Nolletack | J44: 10000 | L44: 10000
B45: Summa | J45: =SUM(J44) -> 10000 | L45: 10000
B47: Kostnader | J47: =SUM(J17:J46)/2 -> 45519 | L47: 69868
B49: Resultat | J49: =J16-J47 -> -35519 | L49: -59868

Sheet NOLL02
A1: NOLL02 | B1: Material
A2: Material till nollningen.
J4: 2026 REV | L4: 2026
A6: Summa intäkter | J6: =J16 -> 0 | L6: =L16 -> 0
A7: Summa utgifter | J7: =J37 -> 42000 | L7: =L37 -> 102000
A8: Resultat | J8: =J6-J7 -> -42000 | L8: =L6-L7 -> -102000
A10: Konto | B10: Namn
A12: 3000 | B12: Försäljning inom Sverige
B13: Vattenballonger | J13: 0 | L13: 0
B14: Summa | J14: =SUM(J13) -> 0 | L14: 0
B16: Intäkter | J16: =SUM(J11:J15)/2 -> 0 | L16: 0
A18: 4000 | B18: Uppdragsmaterial
B19: Plankor m.m. | J19: 10000 | L19: 10000
B20: Cheeroutfits | J20: 2000 | L20: 2000
B21: Vattenballonger | J21: 0 | L21: 0
B22: Summa | J22: =SUM(J19:J20) -> 12000 | L22: 12000
A24: 4320 | B24: Sponsmaterial
B25: Chepsar | J25: 0 | L25: 25000
B26: Nollningströjor | J26: 0 | L26: 35000
B27: Summa | J27: =SUM(J25:J26) -> 0 | L27: 60000
A29: 5480 | B29: Arbetskläder och skyddsmaterial
B30: Stass | J30: 27000 | L30: 27000
B31: Summa | J31: =SUM(J30) -> 27000 | L31: 27000
A33: 6150 | B33: Trycksaker
B34: Väggschema | J34: 3000 | L34: 3000
B35: Summa | J35: =SUM(J34) -> 3000 | L35: 3000
B37: Kostnader | J37: =SUM(J17:J36)/2 -> 42000 | L37: =SUM(L17:L36)/2 -> 102000
B39: Resultat | J39: =J16-J37 -> -42000 | L39: =L16-L37 -> -102000

Sheet NOLL03
A1: NOLL03 | B1: Pepparna
A2: Pepparnas utstyrslar och evenemang.
J4: 2026 REV | L4: 2026
A6: Summa intäkter | J6: =J12 -> 0 | L6: 0
A7: Summa utgifter | J7: =J22 -> 46400 | L7: 46400
A8: Resultat | J8: =J6-J7 -> -46400 | L8: -46400
A10: Konto | B10: Namn
B12: Intäkter | J12: 0 | L12: 0
A14: 5480 | B14: Arbetskläder och skyddsmaterial
B15: Utstyrslar | F15: 11 | G15: × | H15: 900 | I15: = | J15: =F15*H15 -> 9900 | L15: 9900
B16: Summa | J16: =SUM(J15) -> 9900 | L16: 9900
A18: 4310 | B18: Arrangemangskostnader
B19: Peppevenemang | J19: 36500 | L19: 36500
B20: Summa | J20: =SUM(J19) -> 36500 | L20: 36500
B22: Kostnader | J22: =SUM(J13:J21)/2 -> 46400 | L22: 46400
B24: Resultat | J24: =J12-J22 -> -46400 | L24: -46400

Sheet NOLL04
A1: NOLL04 | B1: Evenemang
A2: Evenemang under nollningen.
J4: 2026 REV | L4: 2026
A6: Summa intäkter | J6: =J19 -> 144500 | L6: 104000
A7: Summa utgifter | J7: =J37 -> 194100 | L7: 153600
A8: Resultat | J8: =J6-J7 -> -49600 | L8: -49600
A10: Konto | B10: Namn
A12: 3015 | B12: Biljettfösäljning
B13: FlyING och INGvasion | J13: 40000 | L13: 40000
B14: Phaddersittning | J14: 10000 | L14: 10000
B15: Nationssittning | J15: 54000 | L15: 54000
B16: Teknologkårsmössor | F16: 675 | G16: x | H16: 60 | I16: = | J16: =F16*H16 -> 40500 | L16: 0
B17: Summa | J17: =SUM(J13:J16) -> 144500 | L17: 104000
B19: Intäkter | J19: =SUM(J11:J18)/2 -> 144500 | L19: 104000
A21: 4310 | B21: Arrangemangskostnader
B22: Phaddersittning | J22: 10000 | L22: 10000
B23: Nationssittning | J23: 54000 | L23: 54000
B24: Övriga evenemang | J24: 40000 | L24: 40000
B25: Teknologkårsmössor | F25: 675 | G25: x | H25: 60 | I25: = | J25: =F25*H25 -> 40500 | L25: 0
B26: Summa | J26: =SUM(J22:J25) -> 144500 | L26: 104000
A28: 4730 | B28: Erhållna rabatter
B29: Subventionering | J29: 9600 | L29: 9600
B30: Stabens sittningsbiljetter | L30: 0
B31: Summa | J31: =SUM(J27:J29) -> 9600 | L31: 9600
A33: 5810 | B33: Biljetter
B34: FlyING och INGvasion | J34: 40000 | L34: 40000
B35: Summa | J35: =SUM(J32:J34) -> 40000 | L35: 40000
B37: Kostnader | J37: =SUM(J20:J36)/2 -> 194100 | L37: 153600
B39: Resultat | J39: =J19-J37 -> -49600 | L39: -49600

Sheet SEKT01
A1: SEKT01 | B1: Funktionärer
A2: Saker som gäller alla funktionärer men som inte är tack.
J4: 2026 REV | L4: 2026
A6: Summa intäkter | J6: =J12 -> 0 | L6: 0
A7: Summa utgifter | J7: =J34 -> 4000 | L7: 5000
A8: Resultat | J8: =J6-J7 -> -4000 | L8: -5000
A10: Konto | B10: Namn
B12: Intäkter | J12: 0 | L12: 0
A14: 4330 | B14: Utlottningar och tävlingar
B15: Pris t. D-Compassen | J15: 1000 | L15: 1000
B16: Summa | J16: =SUM(J15) -> 1000 | L16: 1000
A18: 5900 | B18: Reklam och PR
B19: Marknadsföring
B20: Summa | J20: =SUM(J19) -> 0 | L20: 0
A22: 7610 | B22: Utbildning
B23: Funktionärsutbildning | F23: 0 | G23: × | H23: 50 | I23: = | J23: =F23*H23 -> 0 | L23: 0
B24: Summa | J24: =SUM(J23) -> 0 | L24: 0
A26: 7691 | B26: Rekrytering
B27: Sektionspub eller liknande | J27: 3000 | L27: 4000
B28: Summa | J28: =SUM(J27) -> 3000 | L28: 4000
A30: 8610 | B30: Subventionering
B31: Disponibelt | J31: 0 | L31: 0
B32: Summa | J32: =SUM(J31) -> 0 | L32: 0
B34: Kostnader | J34: =SUM(J13:J33)/2 -> 4000 | L34: 5000
B36: Resultat | J36: =J12-J34 -> -4000 | L36: -5000

Sheet SEKT02
A1: SEKT02 | B1: Sektionsmöte
A2: Arrangering av sektionsmöten, sektionens högst beslutande organ. Mellan 4 och 5 brukar arrangeras årligen.
J4: 2026 REV | L4: 2026
A6: Summa intäkter | J6: =J12 -> 0 | L6: 0
A7: Summa utgifter | J7: =J23 -> 23000 | L7: 23000
A8: Resultat | J8: =J6-J7 -> -23000 | L8: -23000
A10: Konto | B10: Namn
B12: Intäkter | J12: 0 | L12: 0
A14: 4000 | B14: Inköp av varor från Sverige
B15: Merch | F15: 0 | G15: × | H15: 4000 | I15: = | J15: =F15*H15 -> 0 | L15: 0
B16: Summa | J16: =SUM(J15) -> 0 | L16: 0
A18: 6450 | B18: Bolagsstämma/års- eller föreningsstämma
B19: Mat | D19: 7 | E19: x | F19: 100 | G19: × | H19: 30 | I19: = | J19: =(D19*F19)*H19 -> 21000 | L19: 21000
B20: Övrigt | J20: 2000 | L20: 2000
B21: Summa | J21: =SUM(J19:J20) -> 23000 | L21: 23000
B23: Kostnader | J23: =SUM(J13:J22)/2 -> 23000 | L23: 23000
B25: Resultat | J25: =J12-J23 -> -23000 | L25: -23000

Sheet SEKT03
A1: SEKT03 | B1: Tack
A2: Tack för alla sektionens funktionärer samt tack och tröjor till förtroendevalda utan utskott.
J4: 2026 | L4: 2026 REV
A6: Summa intäkter | J6: =J12 -> 0 | L6: 0
A7: Summa utgifter | J7: =J29 -> 828 | L7: 2706
A8: Resultat | J8: =J6-J7 -> -828 | L8: -2706
A10: Konto | B10: Namn
B12: Intäkter | J12: 0 | L12: 0
A14: 4000 | B14: Inköp av varor från Sverige
B15: Kvarvarande jubileumsmedaljer | J15: =F15*H15 -> 0 | L15: 0
B16: Summa | J16: =SUM(J15) -> 0 | L16: 0
A18: 5480 | B18: Arbetskläder och skyddsmaterial
B19: Tröjor t. revisorer | J19: 0 | L19: 700
B20: Tröja t. talman | J20: 0 | L20: 350
B21: Summa | J21: =SUM(J19:J20) -> 0 | L21: 1050
A23: 7600 | B23: Tack
B24: Tack t. revisorer | F24: 2 | G24: × | H24: =Parametrar!$I$8 -> 207 | I24: = | J24: =F24*H24 -> 414 | L24: 828
B25: Tack t. talman | J25: =Parametrar!$I$8 -> 207 | L25: 414
B26: Tack t. inspektorn | J26: =Parametrar!$I$8 -> 207 | L26: 414
B27: Summa | J27: =SUM(J24:J26) -> 828 | L27: 1656
B29: Kostnader | J29: =SUM(J14:J28)/2 -> 828 | L29: 2706
B31: Resultat | J31: =J12-J29 -> -828 | L31: -2706

Sheet SEKT05
A1: SEKT05 | B1: Gemensamma kostnader
A2: Kostnader som går ut över alla sektionens utskott.
J4: 2026 REV | L4: 2026
A6: Summa intäkter | J6: =J12 -> 0 | L6: 0
A7: Summa utgifter | J7: =J65 -> 71395 | L7: 65692
A8: Resultat | J8: =J6-J7 -> -71395 | L8: -65692
A10: Konto | B10: Namn
B12: Intäkter | J12: 0 | L12: 0
A14: 5460 | B14: Förbrukningsmaterial
B15: Toner | J15: 5000 | L15: 5000
B16: Rengöringsartiklar osv. | J16: 15000 | L16: 15000
B17: Summa | J17: =SUM(J15:J16) -> 20000 | L17: 20000
A19: 5580 | B19: Underhåll och tvätt av arbetskläder
B20: Tvätt av jobbarkläder | F20: 10 | G20: × | H20: 200 | I20: = | J20: =F20*H20 -> 2000 | L20: 2000
B21: Summa | J21: =SUM(J20) -> 2000 | L21: 2000
A23: 5611 | B23: Drivmedel för personbilar
B24: Bensin t. sektionsbilen | J24: 17000 | L24: 15000
B25: Summa | J25: =SUM(J24) -> 17000 | L25: 15000
A27: 5612 | B27: Försäkring och skatt för personbilar
B28: Skadeförsäkring f. sektionsbilen | J28: 2500 | L28: 2500
B29: Fordonsskatt f. sektionsbilen | J29: 1800 | L29: 1572
B30: Summa | J30: =SUM(J28:J29) -> 4300 | L30: 4072
A32: 5619 | B32: Övriga personbilskostnader
B33: Ny bil | J33: 0 | L33: 0
B34: Parkering vid LTH | F34: 2 | G34: × | H34: 800 | I34: = | J34: =F34*H34 -> 1600 | L34: 1600
B35: Parkering på andra platser | J35: 1000 | L35: 1000
B36: Besiktning | J36: 620 | L36: 620
B37: Summa | J37: =SUM(J33:J36) -> 3220 | L37: 3220
A39: 6070 | B39: Representation
B40: Gåvor t. sektioner, kransar t. begravningar, osv. | J40: 3000 | L40: 3000
B41: Summa | J41: =SUM(J40) -> 3000 | L41: 3000
A43: 6150 | B43: Trycksaker
B44: Informationsutskottet | J44: 0 | L44: 0
B45: Källarmästeriet | J45: 0 | L45: 0
B46: Nollningsutskottet | J46: 0 | L46: 0
B47: Sexmästeriet | J47: 0 | L47: 0
B48: Studierådet | J48: 0 | L48: 0
B49: Näringslivsutskottet | J49: 0 | L49: 0
B50: Cafémästeriet | J50: 0 | L50: 0
B51: Trivselrådet | J51: 0 | L51: 0
...

Sheet SEKT06
A1: SEKT06 | B1: Administration
A2: Administrativa kostnader och intäkter.
J4: 2026 REV | L4: 2026
A6: Summa intäkter | J6: =J16 -> 45000 | L6: 43850
A7: Summa utgifter | J7: =J24 -> 29000 | L7: 21000
A8: Resultat | J8: =J6-J7 -> 16000 | L8: 22850
A10: Konto | B10: Namn
A12: 3990 | B12: Bidrag
B13: Sektionsbidrag | J13: 45000 | L13: 43850
B14: Summa | J14: =SUM(J13) -> 45000 | L14: 43850
B16: Intäkter | J16: =SUM(J11:J15)/2 -> 45000 | L16: 43850
A18: 6950 | B18: Myndighetsavgifter
B19: Stadigvarande tillstånd | J19: 17000 | L19: 10000
B20: PBI-avgift | J20: 6000 | L20: 5000
B21: Livsmedelinspektion | J21: 6000 | L21: 6000
B22: Summa | J22: =SUM(J19:J21) -> 29000 | L22: 21000
B24: Kostnader | J24: =SUM(J17:J23)/2 -> 29000 | L24: 21000
B26: Resultat | J26: =J16-J24 -> 16000 | L26: 22850

Sheet SEKT07
A1: SEKT07 | B1: Jobbardricka
A2: Kaffe, te, choklad och läsk åt funktionärer.
J4: 2026 REV | L4: 2026
A6: Summa intäkter | J6: =J12 -> 0 | L6: 0
A7: Summa utgifter | J7: =J40 -> 36476.14 | L7: 66550
A8: Resultat | J8: =J6-J7 -> -36476.14 | L8: -66550
A10: Konto | B10: Namn
B12: Intäkter | J12: =0 -> 0 | L12: 0
A14: 7603 | B14: Kaffe, te, mjölk och choklad
B15: Kaffe, te, choklad | J15: 10000 | L15: 10000
B16: Summa | J16: =SUM(J15) -> 10000 | L16: 10000
A18: 7602 | B18: Mötesdricka
B19: Cafémästeriet | J19: 3500 | L19: 3500
B20: Centralprocessutskottet | J20: 607.2 | L20: 2850
B21: Nollningsutskottet | J21: 770.46 | L21: 7500
B22: Källarmästeriet | J22: 400 | L22: 3000
B23: Sexmästeriet | J23: 14000 | L23: 14000
B24: Aktivitetutskottet | J24: 777.38 | L24: 2300
B25: Näringslivsutskottet | J25: 118.33 | L25: 1000
B26: Studierådet | J26: 518.81 | L26: 3000
B27: Skattmästeriet | J27: 181.94 | L27: 1100
B28: Informationsutskottet | J28: 317.5 | L28: 1500
B29: Styrelsen diskussionsmöten | J29: 0 | L29: 2000
B30: Styrelsemöten | J30: 0 | L30: 2500
... B36: Tackmästeriet | J36: 0 | L36: 1000
B37: Summa | J37: =SUM(J19:J36) -> 26476.14 | L37: 56550
B40: Kostnader | J40: =SUM(J13:J39)/2 -> 36476.14 | L40: 66550
B42: Resultat | J42: =J12-J40 -> -36476.14 | L42: -66550

Sheet SEKT08
A1: SEKT08 | B1: Fonder
A2: Påfyllning av fonder. För mer detaljer, se policy för fonder.
J4: 2026 REV | L4: 2026
A6: Summa intäkter | J6: =J12 -> 0 | L6: 0
A7: Summa utgifter | J7: =J22 -> 0 | L7: 0
A8: Resultat | J8: =J6-J7 -> 0 | L8: 0
A10: Konto | B10: Namn
B12: Intäkter | J12: 0 | L12: 0
A14: 8811 | B14: Avsättning t. fonder
B15: Inventariefonden | J15: 0 | L15: 0
B16: Bilfonden | J16: 0 | L16: 0
B17: Projektfonden | J17: 0 | L17: 0
B18: Medaljfonden | J18: 0 | L18: 0
B19: Jubileumsfonden | J19: 0 | L19: 0
B20: Summa | J20: =SUM(J15:J19) -> 0 | L20: 0
B22: Kostnader | J22: =SUM(J13:J21)/2 -> 0 | L22: 0
B24: Resultat | J24: =J12-J22 -> 0 | L24: 0

Sheet SEX01
A1: SEX01 | B1: Funktionärer
A2: Mötesfika, tröjor och tack för sexmästeriet.
J4: 2026 REV | L4: 2026
A6: Summa intäkter | J6: =J12 -> 0 | L6: 0
A7: Summa utgifter | J7: =J54 -> 39091 | L7: 45350
A8: Resultat | J8: =J6-J7 -> -39091 | L8: -45350
A10: Konto | B10: Namn
B12: Intäkter | J12: 0 | L12: 0
A14: 4002 | B14: Jobbarmat/Mötesfika
B15: Jobbarmat | D15: 0 | E15: × | F15: 18 | G15: × | H15: 110 | I15: = | J15: =D15*F15*H15 -> 0 | L15: 0
B16: Summa | J16: =SUM(J15) -> 0 | L16: 0
A18: 5480 | B18: Arbetskläder och skyddsmaterial
B19: Kockkläder t. köket | F19: 5 | G19: × | H19: =700 -> 700 | I19: = | J19: =F19*H19 -> 3500 | L19: 3500
B20: Kockkläder t. sektionskockar | F20: 5 | G20: × | H20: =700 -> 700 | I20: = | J20: =F20*H20 -> 3500 | L20: 3500
B21: Jacka t. sexmästare | J21: =Parametrar!$I$9 -> 350 | L21: 350
B22: Jacka t. vice sexmästare | J22: =Parametrar!$I$9 -> 350 | L22: 350
B23: Jacka t. barmästare | J23: =Parametrar!$I$9 -> 350 | L23: 350
B24: Jacka t. hovmästare | J24: =Parametrar!$I$9 -> 350 | L24: 350
B25: Jacka t. köksmästare | J25: =Parametrar!$I$9 -> 350 | L25: 350
B26: Jacka t. pubmästare | J26: =Parametrar!$I$9 -> 350 | L26: 350
B27: Jackor t. vice barmästare | F27: 2 | G27: × | H27: =Parametrar!$I$9 -> 350 | I27: = | J27: =F27*H27 -> 700 | L27: 700
B28: Jackor t. sångförmän | F28: 2 | G28: × | H28: =Parametrar!$I$9 -> 350 | I28: = | J28: =F28*H28 -> 700 | L28: 700
B29: Jackor t. vice pubmästare | F29: 4 | G29: × | H29: =Parametrar!$I$9 -> 350 | I29: = | J29: =F29*H29 -> 1400 | L29: 1050
B30: Jackor t. vice köksmästare | F30: 3 | G30: × | H30: =Parametrar!$I$9 -> 350 | I30: = | J30: =F30*H30 -> 1050 | L30: 1050
B31: Jacka t. preferensmästare | F31: 1 | G31: × | H31: =Parametrar!$I$9 -> 350 | I31: = | J31: =F31*H31 -> 350 | L31: 350
B32: Summa | J32: =SUM(J19:J31) -> 13300 | L32: 12950
A34: 6500 | B34: Övriga externa tjänster (gruppkonto)
B35: Knivbrev | F35: 4 | G35: × | H35: 600 | I35: = | J35: =F35*H35 -> 2400 | L35: 2400
B36: Summa | J36: =SUM(J35) -> 2400 | L36: 2400
A38: 7600 | B38: Tack
B39: Tack t. Precidie | F39: 2 | G39: x | H39: =Parametrar!$I$8 -> 207 | I39: = | J39: =F39*H39 -> 414
B40: Tack t. Köksmästeriet | F40: 5 | G40: × | H40: =Parametrar!$I$8 -> 207 | I40: = | J40: =F40*H40 -> 1035
B41: Tack t. Barmästeriet | F41: 3 | G41: × | H41: =Parametrar!$I$8 -> 207 | I41: = | J41: =F41*H41 -> 621
B42: Tack t. Pubmästeriet | F42: 5 | G42: × | H42: =Parametrar!$I$8 -> 207 | I42: = | J42: =F42*H42 -> 1035
B43: Tack t. Hovmästeriet | F43: 3 | G43: x | H43: =Parametrar!$I$8 -> 207 | J43: =F43*H43 -> 621
B44: Tack t. Vinförmän | F44: 3 | G44: × | H44: =Parametrar!$I$8 -> 207 | I44: = | J44: =F44*H44 -> 621
B45: Tack t. Ölförmännen | F45: 4 | G45: x | H45: =Parametrar!$I$8 -> 207 | J45: =F45*H45 -> 828
B46: Tack t. TappaD | F46: 2 | G46: x | H46: =Parametrar!$I$8 -> 207 | J46: =F46*H46 -> 414
B47: Tack t. Sektionskock | F47: 6 | G47: x | H47: =Parametrar!$I$8 -> 207 | J47: =F47*H47 -> 1242
B48: Summa | J48: =SUM(J39:J47) -> 6831
...

Sheet SEX02
A1: SEX02 | B1: Sittningar
A2: Sexmästeriets sittningar och eftersläpp, exklusive UtEDischot.
J4: 2026 REV | L4: 2026
A6: Summa intäkter | J6: =J33 -> 560705.02 | L6: 390500
A7: Summa utgifter | J7: =J61 -> 522280.86 | L7: 324900
A8: Resultat | J8: =J6-J7 -> 38424.154 | L8: 65600
A10: Konto | B10: Namn
A12: 3000 | B12: Försäljning i Sverige
B13: Märken | J13: 0 | L13: 5000
